[2023-03-02 13:38:23,010] {taskinstance.py:1159} INFO - Dependencies all met for <TaskInstance: avg_product_price.spark_submit manual__2023-03-02T13:38:16.392890+00:00 [queued]>
[2023-03-02 13:38:23,067] {taskinstance.py:1159} INFO - Dependencies all met for <TaskInstance: avg_product_price.spark_submit manual__2023-03-02T13:38:16.392890+00:00 [queued]>
[2023-03-02 13:38:23,069] {taskinstance.py:1356} INFO - 
--------------------------------------------------------------------------------
[2023-03-02 13:38:23,070] {taskinstance.py:1357} INFO - Starting attempt 1 of 2
[2023-03-02 13:38:23,072] {taskinstance.py:1358} INFO - 
--------------------------------------------------------------------------------
[2023-03-02 13:38:23,174] {taskinstance.py:1377} INFO - Executing <Task(SparkSubmitOperator): spark_submit> on 2023-03-02 13:38:16.392890+00:00
[2023-03-02 13:38:23,186] {standard_task_runner.py:52} INFO - Started process 498 to run task
[2023-03-02 13:38:23,193] {standard_task_runner.py:79} INFO - Running: ['***', 'tasks', 'run', 'avg_product_price', 'spark_submit', 'manual__2023-03-02T13:38:16.392890+00:00', '--job-id', '7', '--raw', '--subdir', 'DAGS_FOLDER/avg_product_price.py', '--cfg-path', '/tmp/tmpq18dxh7d', '--error-file', '/tmp/tmpimu0rdh1']
[2023-03-02 13:38:23,199] {standard_task_runner.py:80} INFO - Job 7: Subtask spark_submit
[2023-03-02 13:38:23,380] {task_command.py:370} INFO - Running <TaskInstance: avg_product_price.spark_submit manual__2023-03-02T13:38:16.392890+00:00 [running]> on host 955b42728ca0
[2023-03-02 13:38:23,837] {taskinstance.py:1571} INFO - Exporting the following env vars:
AIRFLOW_CTX_DAG_OWNER=ayyoub
AIRFLOW_CTX_DAG_ID=avg_product_price
AIRFLOW_CTX_TASK_ID=spark_submit
AIRFLOW_CTX_EXECUTION_DATE=2023-03-02T13:38:16.392890+00:00
AIRFLOW_CTX_TRY_NUMBER=1
AIRFLOW_CTX_DAG_RUN_ID=manual__2023-03-02T13:38:16.392890+00:00
[2023-03-02 13:38:23,894] {base.py:68} INFO - Using connection ID 'spark-hadoop' for task execution.
[2023-03-02 13:38:23,898] {spark_submit.py:344} INFO - Spark-Submit cmd: spark-submit --master local[*] --name arrow-spark /hadoop-data/map_reduce/spark/average_price.py
[2023-03-02 13:38:35,819] {spark_submit.py:495} INFO - 23/03/02 13:38:35 INFO SparkContext: Running Spark version 3.3.2
[2023-03-02 13:38:36,228] {spark_submit.py:495} INFO - 23/03/02 13:38:36 WARN NativeCodeLoader: Unable to load native-hadoop library for your platform... using builtin-java classes where applicable
[2023-03-02 13:38:36,802] {spark_submit.py:495} INFO - 23/03/02 13:38:36 INFO ResourceUtils: ==============================================================
[2023-03-02 13:38:36,803] {spark_submit.py:495} INFO - 23/03/02 13:38:36 INFO ResourceUtils: No custom resources configured for spark.driver.
[2023-03-02 13:38:36,804] {spark_submit.py:495} INFO - 23/03/02 13:38:36 INFO ResourceUtils: ==============================================================
[2023-03-02 13:38:36,805] {spark_submit.py:495} INFO - 23/03/02 13:38:36 INFO SparkContext: Submitted application: average_product_price
[2023-03-02 13:38:37,000] {spark_submit.py:495} INFO - 23/03/02 13:38:36 INFO ResourceProfile: Default ResourceProfile created, executor resources: Map(cores -> name: cores, amount: 1, script: , vendor: , memory -> name: memory, amount: 1024, script: , vendor: , offHeap -> name: offHeap, amount: 0, script: , vendor: ), task resources: Map(cpus -> name: cpus, amount: 1.0)
[2023-03-02 13:38:37,059] {spark_submit.py:495} INFO - 23/03/02 13:38:37 INFO ResourceProfile: Limiting resource is cpu
[2023-03-02 13:38:37,060] {spark_submit.py:495} INFO - 23/03/02 13:38:37 INFO ResourceProfileManager: Added ResourceProfile id: 0
[2023-03-02 13:38:37,461] {spark_submit.py:495} INFO - 23/03/02 13:38:37 INFO SecurityManager: Changing view acls to: ***
[2023-03-02 13:38:37,462] {spark_submit.py:495} INFO - 23/03/02 13:38:37 INFO SecurityManager: Changing modify acls to: ***
[2023-03-02 13:38:37,464] {spark_submit.py:495} INFO - 23/03/02 13:38:37 INFO SecurityManager: Changing view acls groups to:
[2023-03-02 13:38:37,466] {spark_submit.py:495} INFO - 23/03/02 13:38:37 INFO SecurityManager: Changing modify acls groups to:
[2023-03-02 13:38:37,467] {spark_submit.py:495} INFO - 23/03/02 13:38:37 INFO SecurityManager: SecurityManager: authentication disabled; ui acls disabled; users  with view permissions: Set(***); groups with view permissions: Set(); users  with modify permissions: Set(***); groups with modify permissions: Set()
[2023-03-02 13:38:38,669] {spark_submit.py:495} INFO - 23/03/02 13:38:38 INFO Utils: Successfully started service 'sparkDriver' on port 36497.
[2023-03-02 13:38:38,841] {spark_submit.py:495} INFO - 23/03/02 13:38:38 INFO SparkEnv: Registering MapOutputTracker
[2023-03-02 13:38:39,061] {spark_submit.py:495} INFO - 23/03/02 13:38:39 INFO SparkEnv: Registering BlockManagerMaster
[2023-03-02 13:38:39,338] {spark_submit.py:495} INFO - 23/03/02 13:38:39 INFO BlockManagerMasterEndpoint: Using org.apache.spark.storage.DefaultTopologyMapper for getting topology information
[2023-03-02 13:38:39,340] {spark_submit.py:495} INFO - 23/03/02 13:38:39 INFO BlockManagerMasterEndpoint: BlockManagerMasterEndpoint up
[2023-03-02 13:38:39,412] {spark_submit.py:495} INFO - 23/03/02 13:38:39 INFO SparkEnv: Registering BlockManagerMasterHeartbeat
[2023-03-02 13:38:39,560] {spark_submit.py:495} INFO - 23/03/02 13:38:39 INFO DiskBlockManager: Created local directory at /tmp/blockmgr-f41107c5-3512-40b6-9d39-47775e749eba
[2023-03-02 13:38:39,697] {spark_submit.py:495} INFO - 23/03/02 13:38:39 INFO MemoryStore: MemoryStore started with capacity 434.4 MiB
[2023-03-02 13:38:41,160] {spark_submit.py:495} INFO - 23/03/02 13:38:41 INFO SparkEnv: Registering OutputCommitCoordinator
[2023-03-02 13:38:44,080] {spark_submit.py:495} INFO - 23/03/02 13:38:44 INFO Utils: Successfully started service 'SparkUI' on port 4040.
[2023-03-02 13:39:06,604] {spark_submit.py:495} INFO - 23/03/02 13:39:05 INFO Executor: Starting executor ID driver on host 955b42728ca0
[2023-03-02 13:39:12,404] {base_job.py:229} ERROR - LocalTaskJob heartbeat got an exception
Traceback (most recent call last):
  File "/usr/local/lib/python3.7/site-packages/sqlalchemy/engine/base.py", line 3141, in _wrap_pool_connect
    return fn()
  File "/usr/local/lib/python3.7/site-packages/sqlalchemy/pool/base.py", line 301, in connect
    return _ConnectionFairy._checkout(self)
  File "/usr/local/lib/python3.7/site-packages/sqlalchemy/pool/base.py", line 755, in _checkout
    fairy = _ConnectionRecord.checkout(pool)
  File "/usr/local/lib/python3.7/site-packages/sqlalchemy/pool/base.py", line 419, in checkout
    rec = pool._do_get()
  File "/usr/local/lib/python3.7/site-packages/sqlalchemy/pool/impl.py", line 259, in _do_get
    return self._create_connection()
  File "/usr/local/lib/python3.7/site-packages/sqlalchemy/pool/base.py", line 247, in _create_connection
    return _ConnectionRecord(self)
  File "/usr/local/lib/python3.7/site-packages/sqlalchemy/pool/base.py", line 362, in __init__
    self.__connect(first_connect_check=True)
  File "/usr/local/lib/python3.7/site-packages/sqlalchemy/pool/base.py", line 605, in __connect
    pool.logger.debug("Error on connect(): %s", e)
  File "/usr/local/lib/python3.7/site-packages/sqlalchemy/util/langhelpers.py", line 72, in __exit__
    with_traceback=exc_tb,
  File "/usr/local/lib/python3.7/site-packages/sqlalchemy/util/compat.py", line 211, in raise_
    raise exception
  File "/usr/local/lib/python3.7/site-packages/sqlalchemy/pool/base.py", line 599, in __connect
    connection = pool._invoke_creator(self)
  File "/usr/local/lib/python3.7/site-packages/sqlalchemy/engine/create.py", line 578, in connect
    return dialect.connect(*cargs, **cparams)
  File "/usr/local/lib/python3.7/site-packages/sqlalchemy/engine/default.py", line 583, in connect
    return self.dbapi.connect(*cargs, **cparams)
  File "/usr/local/lib/python3.7/site-packages/psycopg2/__init__.py", line 122, in connect
    conn = _connect(dsn, connection_factory=connection_factory, **kwasync)
psycopg2.OperationalError: could not translate host name "postgres" to address: Temporary failure in name resolution


The above exception was the direct cause of the following exception:

Traceback (most recent call last):
  File "/usr/local/lib/python3.7/site-packages/airflow/jobs/base_job.py", line 201, in heartbeat
    session.merge(self)
  File "/usr/local/lib/python3.7/site-packages/sqlalchemy/orm/session.py", line 2877, in merge
    _resolve_conflict_map=_resolve_conflict_map,
  File "/usr/local/lib/python3.7/site-packages/sqlalchemy/orm/session.py", line 2950, in _merge
    merged = self.get(mapper.class_, key[1], identity_token=key[2])
  File "/usr/local/lib/python3.7/site-packages/sqlalchemy/orm/session.py", line 2702, in get
    identity_token=identity_token,
  File "/usr/local/lib/python3.7/site-packages/sqlalchemy/orm/session.py", line 2800, in _get_impl
    load_options=load_options,
  File "/usr/local/lib/python3.7/site-packages/sqlalchemy/orm/loading.py", line 535, in load_on_pk_identity
    bind_arguments=bind_arguments,
  File "/usr/local/lib/python3.7/site-packages/sqlalchemy/orm/session.py", line 1669, in execute
    conn = self._connection_for_bind(bind, close_with_result=True)
  File "/usr/local/lib/python3.7/site-packages/sqlalchemy/orm/session.py", line 1520, in _connection_for_bind
    engine, execution_options
  File "/usr/local/lib/python3.7/site-packages/sqlalchemy/orm/session.py", line 747, in _connection_for_bind
    conn = bind.connect()
  File "/usr/local/lib/python3.7/site-packages/sqlalchemy/engine/base.py", line 3095, in connect
    return self._connection_cls(self, close_with_result=close_with_result)
  File "/usr/local/lib/python3.7/site-packages/sqlalchemy/engine/base.py", line 91, in __init__
    else engine.raw_connection()
  File "/usr/local/lib/python3.7/site-packages/sqlalchemy/engine/base.py", line 3174, in raw_connection
    return self._wrap_pool_connect(self.pool.connect, _connection)
  File "/usr/local/lib/python3.7/site-packages/sqlalchemy/engine/base.py", line 3145, in _wrap_pool_connect
    e, dialect, self
  File "/usr/local/lib/python3.7/site-packages/sqlalchemy/engine/base.py", line 2004, in _handle_dbapi_exception_noconnection
    sqlalchemy_exception, with_traceback=exc_info[2], from_=e
  File "/usr/local/lib/python3.7/site-packages/sqlalchemy/util/compat.py", line 211, in raise_
    raise exception
  File "/usr/local/lib/python3.7/site-packages/sqlalchemy/engine/base.py", line 3141, in _wrap_pool_connect
    return fn()
  File "/usr/local/lib/python3.7/site-packages/sqlalchemy/pool/base.py", line 301, in connect
    return _ConnectionFairy._checkout(self)
  File "/usr/local/lib/python3.7/site-packages/sqlalchemy/pool/base.py", line 755, in _checkout
    fairy = _ConnectionRecord.checkout(pool)
  File "/usr/local/lib/python3.7/site-packages/sqlalchemy/pool/base.py", line 419, in checkout
    rec = pool._do_get()
  File "/usr/local/lib/python3.7/site-packages/sqlalchemy/pool/impl.py", line 259, in _do_get
    return self._create_connection()
  File "/usr/local/lib/python3.7/site-packages/sqlalchemy/pool/base.py", line 247, in _create_connection
    return _ConnectionRecord(self)
  File "/usr/local/lib/python3.7/site-packages/sqlalchemy/pool/base.py", line 362, in __init__
    self.__connect(first_connect_check=True)
  File "/usr/local/lib/python3.7/site-packages/sqlalchemy/pool/base.py", line 605, in __connect
    pool.logger.debug("Error on connect(): %s", e)
  File "/usr/local/lib/python3.7/site-packages/sqlalchemy/util/langhelpers.py", line 72, in __exit__
    with_traceback=exc_tb,
  File "/usr/local/lib/python3.7/site-packages/sqlalchemy/util/compat.py", line 211, in raise_
    raise exception
  File "/usr/local/lib/python3.7/site-packages/sqlalchemy/pool/base.py", line 599, in __connect
    connection = pool._invoke_creator(self)
  File "/usr/local/lib/python3.7/site-packages/sqlalchemy/engine/create.py", line 578, in connect
    return dialect.connect(*cargs, **cparams)
  File "/usr/local/lib/python3.7/site-packages/sqlalchemy/engine/default.py", line 583, in connect
    return self.dbapi.connect(*cargs, **cparams)
  File "/usr/local/lib/python3.7/site-packages/psycopg2/__init__.py", line 122, in connect
    conn = _connect(dsn, connection_factory=connection_factory, **kwasync)
sqlalchemy.exc.OperationalError: (psycopg2.OperationalError) could not translate host name "postgres" to address: Temporary failure in name resolution

(Background on this error at: http://sqlalche.me/e/14/e3q8)
[2023-03-02 13:39:35,101] {spark_submit.py:495} INFO - 23/03/02 13:39:35 INFO Executor: Starting executor with user classpath (userClassPathFirst = false): ''
[2023-03-02 13:39:51,492] {spark_submit.py:495} INFO - 23/03/02 13:39:51 INFO Utils: Successfully started service 'org.apache.spark.network.netty.NettyBlockTransferService' on port 40329.
[2023-03-02 13:39:51,527] {spark_submit.py:495} INFO - 23/03/02 13:39:51 INFO NettyBlockTransferService: Server created on 955b42728ca0:40329
[2023-03-02 13:39:51,723] {spark_submit.py:495} INFO - 23/03/02 13:39:51 INFO BlockManager: Using org.apache.spark.storage.RandomBlockReplicationPolicy for block replication policy
[2023-03-02 13:39:52,251] {spark_submit.py:495} INFO - 23/03/02 13:39:52 INFO BlockManagerMaster: Registering BlockManager BlockManagerId(driver, 955b42728ca0, 40329, None)
[2023-03-02 13:39:52,504] {spark_submit.py:495} INFO - 23/03/02 13:39:52 INFO BlockManagerMasterEndpoint: Registering block manager 955b42728ca0:40329 with 434.4 MiB RAM, BlockManagerId(driver, 955b42728ca0, 40329, None)
[2023-03-02 13:39:52,585] {spark_submit.py:495} INFO - 23/03/02 13:39:52 INFO BlockManagerMaster: Registered BlockManager BlockManagerId(driver, 955b42728ca0, 40329, None)
[2023-03-02 13:39:52,627] {spark_submit.py:495} INFO - 23/03/02 13:39:52 INFO BlockManager: Initialized BlockManager: BlockManagerId(driver, 955b42728ca0, 40329, None)
[2023-03-02 13:39:59,794] {spark_submit.py:495} INFO - /opt/spark-3.3.2-bin-hadoop3/python/lib/pyspark.zip/pyspark/sql/context.py:114: FutureWarning: Deprecated in 3.0.0. Use SparkSession.builder.getOrCreate() instead.
[2023-03-02 13:40:01,101] {spark_submit.py:495} INFO - 23/03/02 13:40:01 INFO SharedState: Setting hive.metastore.warehouse.dir ('null') to the value of spark.sql.warehouse.dir.
[2023-03-02 13:40:01,176] {spark_submit.py:495} INFO - 23/03/02 13:40:01 INFO SharedState: Warehouse path is 'file:/home/***/spark-warehouse'.
[2023-03-02 13:40:36,893] {base_job.py:229} ERROR - LocalTaskJob heartbeat got an exception
Traceback (most recent call last):
  File "/usr/local/lib/python3.7/site-packages/sqlalchemy/engine/base.py", line 3141, in _wrap_pool_connect
    return fn()
  File "/usr/local/lib/python3.7/site-packages/sqlalchemy/pool/base.py", line 301, in connect
    return _ConnectionFairy._checkout(self)
  File "/usr/local/lib/python3.7/site-packages/sqlalchemy/pool/base.py", line 755, in _checkout
    fairy = _ConnectionRecord.checkout(pool)
  File "/usr/local/lib/python3.7/site-packages/sqlalchemy/pool/base.py", line 419, in checkout
    rec = pool._do_get()
  File "/usr/local/lib/python3.7/site-packages/sqlalchemy/pool/impl.py", line 259, in _do_get
    return self._create_connection()
  File "/usr/local/lib/python3.7/site-packages/sqlalchemy/pool/base.py", line 247, in _create_connection
    return _ConnectionRecord(self)
  File "/usr/local/lib/python3.7/site-packages/sqlalchemy/pool/base.py", line 362, in __init__
    self.__connect(first_connect_check=True)
  File "/usr/local/lib/python3.7/site-packages/sqlalchemy/pool/base.py", line 605, in __connect
    pool.logger.debug("Error on connect(): %s", e)
  File "/usr/local/lib/python3.7/site-packages/sqlalchemy/util/langhelpers.py", line 72, in __exit__
    with_traceback=exc_tb,
  File "/usr/local/lib/python3.7/site-packages/sqlalchemy/util/compat.py", line 211, in raise_
    raise exception
  File "/usr/local/lib/python3.7/site-packages/sqlalchemy/pool/base.py", line 599, in __connect
    connection = pool._invoke_creator(self)
  File "/usr/local/lib/python3.7/site-packages/sqlalchemy/engine/create.py", line 578, in connect
    return dialect.connect(*cargs, **cparams)
  File "/usr/local/lib/python3.7/site-packages/sqlalchemy/engine/default.py", line 583, in connect
    return self.dbapi.connect(*cargs, **cparams)
  File "/usr/local/lib/python3.7/site-packages/psycopg2/__init__.py", line 122, in connect
    conn = _connect(dsn, connection_factory=connection_factory, **kwasync)
psycopg2.OperationalError: could not translate host name "postgres" to address: Temporary failure in name resolution


The above exception was the direct cause of the following exception:

Traceback (most recent call last):
  File "/usr/local/lib/python3.7/site-packages/airflow/jobs/base_job.py", line 201, in heartbeat
    session.merge(self)
  File "/usr/local/lib/python3.7/site-packages/sqlalchemy/orm/session.py", line 2877, in merge
    _resolve_conflict_map=_resolve_conflict_map,
  File "/usr/local/lib/python3.7/site-packages/sqlalchemy/orm/session.py", line 2950, in _merge
    merged = self.get(mapper.class_, key[1], identity_token=key[2])
  File "/usr/local/lib/python3.7/site-packages/sqlalchemy/orm/session.py", line 2702, in get
    identity_token=identity_token,
  File "/usr/local/lib/python3.7/site-packages/sqlalchemy/orm/session.py", line 2800, in _get_impl
    load_options=load_options,
  File "/usr/local/lib/python3.7/site-packages/sqlalchemy/orm/loading.py", line 535, in load_on_pk_identity
    bind_arguments=bind_arguments,
  File "/usr/local/lib/python3.7/site-packages/sqlalchemy/orm/session.py", line 1669, in execute
    conn = self._connection_for_bind(bind, close_with_result=True)
  File "/usr/local/lib/python3.7/site-packages/sqlalchemy/orm/session.py", line 1520, in _connection_for_bind
    engine, execution_options
  File "/usr/local/lib/python3.7/site-packages/sqlalchemy/orm/session.py", line 747, in _connection_for_bind
    conn = bind.connect()
  File "/usr/local/lib/python3.7/site-packages/sqlalchemy/engine/base.py", line 3095, in connect
    return self._connection_cls(self, close_with_result=close_with_result)
  File "/usr/local/lib/python3.7/site-packages/sqlalchemy/engine/base.py", line 91, in __init__
    else engine.raw_connection()
  File "/usr/local/lib/python3.7/site-packages/sqlalchemy/engine/base.py", line 3174, in raw_connection
    return self._wrap_pool_connect(self.pool.connect, _connection)
  File "/usr/local/lib/python3.7/site-packages/sqlalchemy/engine/base.py", line 3145, in _wrap_pool_connect
    e, dialect, self
  File "/usr/local/lib/python3.7/site-packages/sqlalchemy/engine/base.py", line 2004, in _handle_dbapi_exception_noconnection
    sqlalchemy_exception, with_traceback=exc_info[2], from_=e
  File "/usr/local/lib/python3.7/site-packages/sqlalchemy/util/compat.py", line 211, in raise_
    raise exception
  File "/usr/local/lib/python3.7/site-packages/sqlalchemy/engine/base.py", line 3141, in _wrap_pool_connect
    return fn()
  File "/usr/local/lib/python3.7/site-packages/sqlalchemy/pool/base.py", line 301, in connect
    return _ConnectionFairy._checkout(self)
  File "/usr/local/lib/python3.7/site-packages/sqlalchemy/pool/base.py", line 755, in _checkout
    fairy = _ConnectionRecord.checkout(pool)
  File "/usr/local/lib/python3.7/site-packages/sqlalchemy/pool/base.py", line 419, in checkout
    rec = pool._do_get()
  File "/usr/local/lib/python3.7/site-packages/sqlalchemy/pool/impl.py", line 259, in _do_get
    return self._create_connection()
  File "/usr/local/lib/python3.7/site-packages/sqlalchemy/pool/base.py", line 247, in _create_connection
    return _ConnectionRecord(self)
  File "/usr/local/lib/python3.7/site-packages/sqlalchemy/pool/base.py", line 362, in __init__
    self.__connect(first_connect_check=True)
  File "/usr/local/lib/python3.7/site-packages/sqlalchemy/pool/base.py", line 605, in __connect
    pool.logger.debug("Error on connect(): %s", e)
  File "/usr/local/lib/python3.7/site-packages/sqlalchemy/util/langhelpers.py", line 72, in __exit__
    with_traceback=exc_tb,
  File "/usr/local/lib/python3.7/site-packages/sqlalchemy/util/compat.py", line 211, in raise_
    raise exception
  File "/usr/local/lib/python3.7/site-packages/sqlalchemy/pool/base.py", line 599, in __connect
    connection = pool._invoke_creator(self)
  File "/usr/local/lib/python3.7/site-packages/sqlalchemy/engine/create.py", line 578, in connect
    return dialect.connect(*cargs, **cparams)
  File "/usr/local/lib/python3.7/site-packages/sqlalchemy/engine/default.py", line 583, in connect
    return self.dbapi.connect(*cargs, **cparams)
  File "/usr/local/lib/python3.7/site-packages/psycopg2/__init__.py", line 122, in connect
    conn = _connect(dsn, connection_factory=connection_factory, **kwasync)
sqlalchemy.exc.OperationalError: (psycopg2.OperationalError) could not translate host name "postgres" to address: Temporary failure in name resolution

(Background on this error at: http://sqlalche.me/e/14/e3q8)
[2023-03-02 13:40:56,152] {base_job.py:229} ERROR - LocalTaskJob heartbeat got an exception
Traceback (most recent call last):
  File "/usr/local/lib/python3.7/site-packages/sqlalchemy/engine/base.py", line 3141, in _wrap_pool_connect
    return fn()
  File "/usr/local/lib/python3.7/site-packages/sqlalchemy/pool/base.py", line 301, in connect
    return _ConnectionFairy._checkout(self)
  File "/usr/local/lib/python3.7/site-packages/sqlalchemy/pool/base.py", line 755, in _checkout
    fairy = _ConnectionRecord.checkout(pool)
  File "/usr/local/lib/python3.7/site-packages/sqlalchemy/pool/base.py", line 419, in checkout
    rec = pool._do_get()
  File "/usr/local/lib/python3.7/site-packages/sqlalchemy/pool/impl.py", line 259, in _do_get
    return self._create_connection()
  File "/usr/local/lib/python3.7/site-packages/sqlalchemy/pool/base.py", line 247, in _create_connection
    return _ConnectionRecord(self)
  File "/usr/local/lib/python3.7/site-packages/sqlalchemy/pool/base.py", line 362, in __init__
    self.__connect(first_connect_check=True)
  File "/usr/local/lib/python3.7/site-packages/sqlalchemy/pool/base.py", line 605, in __connect
    pool.logger.debug("Error on connect(): %s", e)
  File "/usr/local/lib/python3.7/site-packages/sqlalchemy/util/langhelpers.py", line 72, in __exit__
    with_traceback=exc_tb,
  File "/usr/local/lib/python3.7/site-packages/sqlalchemy/util/compat.py", line 211, in raise_
    raise exception
  File "/usr/local/lib/python3.7/site-packages/sqlalchemy/pool/base.py", line 599, in __connect
    connection = pool._invoke_creator(self)
  File "/usr/local/lib/python3.7/site-packages/sqlalchemy/engine/create.py", line 578, in connect
    return dialect.connect(*cargs, **cparams)
  File "/usr/local/lib/python3.7/site-packages/sqlalchemy/engine/default.py", line 583, in connect
    return self.dbapi.connect(*cargs, **cparams)
  File "/usr/local/lib/python3.7/site-packages/psycopg2/__init__.py", line 122, in connect
    conn = _connect(dsn, connection_factory=connection_factory, **kwasync)
psycopg2.OperationalError: could not translate host name "postgres" to address: Temporary failure in name resolution


The above exception was the direct cause of the following exception:

Traceback (most recent call last):
  File "/usr/local/lib/python3.7/site-packages/airflow/jobs/base_job.py", line 201, in heartbeat
    session.merge(self)
  File "/usr/local/lib/python3.7/site-packages/sqlalchemy/orm/session.py", line 2877, in merge
    _resolve_conflict_map=_resolve_conflict_map,
  File "/usr/local/lib/python3.7/site-packages/sqlalchemy/orm/session.py", line 2950, in _merge
    merged = self.get(mapper.class_, key[1], identity_token=key[2])
  File "/usr/local/lib/python3.7/site-packages/sqlalchemy/orm/session.py", line 2702, in get
    identity_token=identity_token,
  File "/usr/local/lib/python3.7/site-packages/sqlalchemy/orm/session.py", line 2800, in _get_impl
    load_options=load_options,
  File "/usr/local/lib/python3.7/site-packages/sqlalchemy/orm/loading.py", line 535, in load_on_pk_identity
    bind_arguments=bind_arguments,
  File "/usr/local/lib/python3.7/site-packages/sqlalchemy/orm/session.py", line 1669, in execute
    conn = self._connection_for_bind(bind, close_with_result=True)
  File "/usr/local/lib/python3.7/site-packages/sqlalchemy/orm/session.py", line 1520, in _connection_for_bind
    engine, execution_options
  File "/usr/local/lib/python3.7/site-packages/sqlalchemy/orm/session.py", line 747, in _connection_for_bind
    conn = bind.connect()
  File "/usr/local/lib/python3.7/site-packages/sqlalchemy/engine/base.py", line 3095, in connect
    return self._connection_cls(self, close_with_result=close_with_result)
  File "/usr/local/lib/python3.7/site-packages/sqlalchemy/engine/base.py", line 91, in __init__
    else engine.raw_connection()
  File "/usr/local/lib/python3.7/site-packages/sqlalchemy/engine/base.py", line 3174, in raw_connection
    return self._wrap_pool_connect(self.pool.connect, _connection)
  File "/usr/local/lib/python3.7/site-packages/sqlalchemy/engine/base.py", line 3145, in _wrap_pool_connect
    e, dialect, self
  File "/usr/local/lib/python3.7/site-packages/sqlalchemy/engine/base.py", line 2004, in _handle_dbapi_exception_noconnection
    sqlalchemy_exception, with_traceback=exc_info[2], from_=e
  File "/usr/local/lib/python3.7/site-packages/sqlalchemy/util/compat.py", line 211, in raise_
    raise exception
  File "/usr/local/lib/python3.7/site-packages/sqlalchemy/engine/base.py", line 3141, in _wrap_pool_connect
    return fn()
  File "/usr/local/lib/python3.7/site-packages/sqlalchemy/pool/base.py", line 301, in connect
    return _ConnectionFairy._checkout(self)
  File "/usr/local/lib/python3.7/site-packages/sqlalchemy/pool/base.py", line 755, in _checkout
    fairy = _ConnectionRecord.checkout(pool)
  File "/usr/local/lib/python3.7/site-packages/sqlalchemy/pool/base.py", line 419, in checkout
    rec = pool._do_get()
  File "/usr/local/lib/python3.7/site-packages/sqlalchemy/pool/impl.py", line 259, in _do_get
    return self._create_connection()
  File "/usr/local/lib/python3.7/site-packages/sqlalchemy/pool/base.py", line 247, in _create_connection
    return _ConnectionRecord(self)
  File "/usr/local/lib/python3.7/site-packages/sqlalchemy/pool/base.py", line 362, in __init__
    self.__connect(first_connect_check=True)
  File "/usr/local/lib/python3.7/site-packages/sqlalchemy/pool/base.py", line 605, in __connect
    pool.logger.debug("Error on connect(): %s", e)
  File "/usr/local/lib/python3.7/site-packages/sqlalchemy/util/langhelpers.py", line 72, in __exit__
    with_traceback=exc_tb,
  File "/usr/local/lib/python3.7/site-packages/sqlalchemy/util/compat.py", line 211, in raise_
    raise exception
  File "/usr/local/lib/python3.7/site-packages/sqlalchemy/pool/base.py", line 599, in __connect
    connection = pool._invoke_creator(self)
  File "/usr/local/lib/python3.7/site-packages/sqlalchemy/engine/create.py", line 578, in connect
    return dialect.connect(*cargs, **cparams)
  File "/usr/local/lib/python3.7/site-packages/sqlalchemy/engine/default.py", line 583, in connect
    return self.dbapi.connect(*cargs, **cparams)
  File "/usr/local/lib/python3.7/site-packages/psycopg2/__init__.py", line 122, in connect
    conn = _connect(dsn, connection_factory=connection_factory, **kwasync)
sqlalchemy.exc.OperationalError: (psycopg2.OperationalError) could not translate host name "postgres" to address: Temporary failure in name resolution

(Background on this error at: http://sqlalche.me/e/14/e3q8)
[2023-03-02 13:41:16,805] {spark_submit.py:495} INFO - 23/03/02 13:41:14 WARN NettyRpcEnv: Ignored failure: java.util.concurrent.TimeoutException: Cannot receive any reply from 955b42728ca0:36497 in 10000 milliseconds
[2023-03-02 13:41:31,970] {base_job.py:229} ERROR - LocalTaskJob heartbeat got an exception
Traceback (most recent call last):
  File "/usr/local/lib/python3.7/site-packages/sqlalchemy/engine/base.py", line 3141, in _wrap_pool_connect
    return fn()
  File "/usr/local/lib/python3.7/site-packages/sqlalchemy/pool/base.py", line 301, in connect
    return _ConnectionFairy._checkout(self)
  File "/usr/local/lib/python3.7/site-packages/sqlalchemy/pool/base.py", line 755, in _checkout
    fairy = _ConnectionRecord.checkout(pool)
  File "/usr/local/lib/python3.7/site-packages/sqlalchemy/pool/base.py", line 419, in checkout
    rec = pool._do_get()
  File "/usr/local/lib/python3.7/site-packages/sqlalchemy/pool/impl.py", line 259, in _do_get
    return self._create_connection()
  File "/usr/local/lib/python3.7/site-packages/sqlalchemy/pool/base.py", line 247, in _create_connection
    return _ConnectionRecord(self)
  File "/usr/local/lib/python3.7/site-packages/sqlalchemy/pool/base.py", line 362, in __init__
    self.__connect(first_connect_check=True)
  File "/usr/local/lib/python3.7/site-packages/sqlalchemy/pool/base.py", line 605, in __connect
    pool.logger.debug("Error on connect(): %s", e)
  File "/usr/local/lib/python3.7/site-packages/sqlalchemy/util/langhelpers.py", line 72, in __exit__
    with_traceback=exc_tb,
  File "/usr/local/lib/python3.7/site-packages/sqlalchemy/util/compat.py", line 211, in raise_
    raise exception
  File "/usr/local/lib/python3.7/site-packages/sqlalchemy/pool/base.py", line 599, in __connect
    connection = pool._invoke_creator(self)
  File "/usr/local/lib/python3.7/site-packages/sqlalchemy/engine/create.py", line 578, in connect
    return dialect.connect(*cargs, **cparams)
  File "/usr/local/lib/python3.7/site-packages/sqlalchemy/engine/default.py", line 583, in connect
    return self.dbapi.connect(*cargs, **cparams)
  File "/usr/local/lib/python3.7/site-packages/psycopg2/__init__.py", line 122, in connect
    conn = _connect(dsn, connection_factory=connection_factory, **kwasync)
psycopg2.OperationalError: could not translate host name "postgres" to address: Temporary failure in name resolution


The above exception was the direct cause of the following exception:

Traceback (most recent call last):
  File "/usr/local/lib/python3.7/site-packages/airflow/jobs/base_job.py", line 201, in heartbeat
    session.merge(self)
  File "/usr/local/lib/python3.7/site-packages/sqlalchemy/orm/session.py", line 2877, in merge
    _resolve_conflict_map=_resolve_conflict_map,
  File "/usr/local/lib/python3.7/site-packages/sqlalchemy/orm/session.py", line 2950, in _merge
    merged = self.get(mapper.class_, key[1], identity_token=key[2])
  File "/usr/local/lib/python3.7/site-packages/sqlalchemy/orm/session.py", line 2702, in get
    identity_token=identity_token,
  File "/usr/local/lib/python3.7/site-packages/sqlalchemy/orm/session.py", line 2800, in _get_impl
    load_options=load_options,
  File "/usr/local/lib/python3.7/site-packages/sqlalchemy/orm/loading.py", line 535, in load_on_pk_identity
    bind_arguments=bind_arguments,
  File "/usr/local/lib/python3.7/site-packages/sqlalchemy/orm/session.py", line 1669, in execute
    conn = self._connection_for_bind(bind, close_with_result=True)
  File "/usr/local/lib/python3.7/site-packages/sqlalchemy/orm/session.py", line 1520, in _connection_for_bind
    engine, execution_options
  File "/usr/local/lib/python3.7/site-packages/sqlalchemy/orm/session.py", line 747, in _connection_for_bind
    conn = bind.connect()
  File "/usr/local/lib/python3.7/site-packages/sqlalchemy/engine/base.py", line 3095, in connect
    return self._connection_cls(self, close_with_result=close_with_result)
  File "/usr/local/lib/python3.7/site-packages/sqlalchemy/engine/base.py", line 91, in __init__
    else engine.raw_connection()
  File "/usr/local/lib/python3.7/site-packages/sqlalchemy/engine/base.py", line 3174, in raw_connection
    return self._wrap_pool_connect(self.pool.connect, _connection)
  File "/usr/local/lib/python3.7/site-packages/sqlalchemy/engine/base.py", line 3145, in _wrap_pool_connect
    e, dialect, self
  File "/usr/local/lib/python3.7/site-packages/sqlalchemy/engine/base.py", line 2004, in _handle_dbapi_exception_noconnection
    sqlalchemy_exception, with_traceback=exc_info[2], from_=e
  File "/usr/local/lib/python3.7/site-packages/sqlalchemy/util/compat.py", line 211, in raise_
    raise exception
  File "/usr/local/lib/python3.7/site-packages/sqlalchemy/engine/base.py", line 3141, in _wrap_pool_connect
    return fn()
  File "/usr/local/lib/python3.7/site-packages/sqlalchemy/pool/base.py", line 301, in connect
    return _ConnectionFairy._checkout(self)
  File "/usr/local/lib/python3.7/site-packages/sqlalchemy/pool/base.py", line 755, in _checkout
    fairy = _ConnectionRecord.checkout(pool)
  File "/usr/local/lib/python3.7/site-packages/sqlalchemy/pool/base.py", line 419, in checkout
    rec = pool._do_get()
  File "/usr/local/lib/python3.7/site-packages/sqlalchemy/pool/impl.py", line 259, in _do_get
    return self._create_connection()
  File "/usr/local/lib/python3.7/site-packages/sqlalchemy/pool/base.py", line 247, in _create_connection
    return _ConnectionRecord(self)
  File "/usr/local/lib/python3.7/site-packages/sqlalchemy/pool/base.py", line 362, in __init__
    self.__connect(first_connect_check=True)
  File "/usr/local/lib/python3.7/site-packages/sqlalchemy/pool/base.py", line 605, in __connect
    pool.logger.debug("Error on connect(): %s", e)
  File "/usr/local/lib/python3.7/site-packages/sqlalchemy/util/langhelpers.py", line 72, in __exit__
    with_traceback=exc_tb,
  File "/usr/local/lib/python3.7/site-packages/sqlalchemy/util/compat.py", line 211, in raise_
    raise exception
  File "/usr/local/lib/python3.7/site-packages/sqlalchemy/pool/base.py", line 599, in __connect
    connection = pool._invoke_creator(self)
  File "/usr/local/lib/python3.7/site-packages/sqlalchemy/engine/create.py", line 578, in connect
    return dialect.connect(*cargs, **cparams)
  File "/usr/local/lib/python3.7/site-packages/sqlalchemy/engine/default.py", line 583, in connect
    return self.dbapi.connect(*cargs, **cparams)
  File "/usr/local/lib/python3.7/site-packages/psycopg2/__init__.py", line 122, in connect
    conn = _connect(dsn, connection_factory=connection_factory, **kwasync)
sqlalchemy.exc.OperationalError: (psycopg2.OperationalError) could not translate host name "postgres" to address: Temporary failure in name resolution

(Background on this error at: http://sqlalche.me/e/14/e3q8)
[2023-03-02 13:42:01,146] {spark_submit.py:495} INFO - 23/03/02 13:41:58 WARN Executor: Issue communicating with driver in heartbeater
[2023-03-02 13:42:01,309] {spark_submit.py:495} INFO - org.apache.spark.rpc.RpcTimeoutException: Futures timed out after [10000 milliseconds]. This timeout is controlled by spark.executor.heartbeatInterval
[2023-03-02 13:42:01,310] {spark_submit.py:495} INFO - at org.apache.spark.rpc.RpcTimeout.org$apache$spark$rpc$RpcTimeout$$createRpcTimeoutException(RpcTimeout.scala:47)
[2023-03-02 13:42:01,312] {spark_submit.py:495} INFO - at org.apache.spark.rpc.RpcTimeout$$anonfun$addMessageIfTimeout$1.applyOrElse(RpcTimeout.scala:62)
[2023-03-02 13:42:01,314] {spark_submit.py:495} INFO - at org.apache.spark.rpc.RpcTimeout$$anonfun$addMessageIfTimeout$1.applyOrElse(RpcTimeout.scala:58)
[2023-03-02 13:42:01,315] {spark_submit.py:495} INFO - at scala.runtime.AbstractPartialFunction.apply(AbstractPartialFunction.scala:38)
[2023-03-02 13:42:01,316] {spark_submit.py:495} INFO - at org.apache.spark.rpc.RpcTimeout.awaitResult(RpcTimeout.scala:76)
[2023-03-02 13:42:01,318] {spark_submit.py:495} INFO - at org.apache.spark.rpc.RpcEndpointRef.askSync(RpcEndpointRef.scala:103)
[2023-03-02 13:42:01,319] {spark_submit.py:495} INFO - at org.apache.spark.executor.Executor.reportHeartBeat(Executor.scala:1053)
[2023-03-02 13:42:01,321] {spark_submit.py:495} INFO - at org.apache.spark.executor.Executor.$anonfun$heartbeater$1(Executor.scala:238)
[2023-03-02 13:42:01,322] {spark_submit.py:495} INFO - at scala.runtime.java8.JFunction0$mcV$sp.apply(JFunction0$mcV$sp.java:23)
[2023-03-02 13:42:01,324] {spark_submit.py:495} INFO - at org.apache.spark.util.Utils$.logUncaughtExceptions(Utils.scala:2066)
[2023-03-02 13:42:01,325] {spark_submit.py:495} INFO - at org.apache.spark.Heartbeater$$anon$1.run(Heartbeater.scala:46)
[2023-03-02 13:42:01,326] {spark_submit.py:495} INFO - at java.base/java.util.concurrent.Executors$RunnableAdapter.call(Executors.java:515)
[2023-03-02 13:42:01,328] {spark_submit.py:495} INFO - at java.base/java.util.concurrent.FutureTask.runAndReset(FutureTask.java:305)
[2023-03-02 13:42:01,330] {spark_submit.py:495} INFO - at java.base/java.util.concurrent.ScheduledThreadPoolExecutor$ScheduledFutureTask.run(ScheduledThreadPoolExecutor.java:305)
[2023-03-02 13:42:01,331] {spark_submit.py:495} INFO - at java.base/java.util.concurrent.ThreadPoolExecutor.runWorker(ThreadPoolExecutor.java:1128)
[2023-03-02 13:42:01,333] {spark_submit.py:495} INFO - at java.base/java.util.concurrent.ThreadPoolExecutor$Worker.run(ThreadPoolExecutor.java:628)
[2023-03-02 13:42:01,335] {spark_submit.py:495} INFO - at java.base/java.lang.Thread.run(Thread.java:829)
[2023-03-02 13:42:01,337] {spark_submit.py:495} INFO - Caused by: java.util.concurrent.TimeoutException: Futures timed out after [10000 milliseconds]
[2023-03-02 13:42:01,339] {spark_submit.py:495} INFO - at scala.concurrent.impl.Promise$DefaultPromise.ready(Promise.scala:259)
[2023-03-02 13:42:01,341] {spark_submit.py:495} INFO - at scala.concurrent.impl.Promise$DefaultPromise.result(Promise.scala:263)
[2023-03-02 13:42:01,342] {spark_submit.py:495} INFO - at org.apache.spark.util.ThreadUtils$.awaitResult(ThreadUtils.scala:293)
[2023-03-02 13:42:01,343] {spark_submit.py:495} INFO - at org.apache.spark.rpc.RpcTimeout.awaitResult(RpcTimeout.scala:75)
[2023-03-02 13:42:01,345] {spark_submit.py:495} INFO - ... 12 more
[2023-03-02 13:42:01,347] {spark_submit.py:495} INFO - 23/03/02 13:42:01 INFO AsyncEventQueue: Process of event SparkListenerExecutorMetricsUpdate(driver,WrappedArray(),Map((-1,-1) -> org.apache.spark.executor.ExecutorMetrics@13715493)) by listener AppStatusListener took 3.968146895s.
[2023-03-02 13:42:02,686] {base_job.py:229} ERROR - LocalTaskJob heartbeat got an exception
Traceback (most recent call last):
  File "/usr/local/lib/python3.7/site-packages/sqlalchemy/engine/base.py", line 3141, in _wrap_pool_connect
    return fn()
  File "/usr/local/lib/python3.7/site-packages/sqlalchemy/pool/base.py", line 301, in connect
    return _ConnectionFairy._checkout(self)
  File "/usr/local/lib/python3.7/site-packages/sqlalchemy/pool/base.py", line 755, in _checkout
    fairy = _ConnectionRecord.checkout(pool)
  File "/usr/local/lib/python3.7/site-packages/sqlalchemy/pool/base.py", line 419, in checkout
    rec = pool._do_get()
  File "/usr/local/lib/python3.7/site-packages/sqlalchemy/pool/impl.py", line 259, in _do_get
    return self._create_connection()
  File "/usr/local/lib/python3.7/site-packages/sqlalchemy/pool/base.py", line 247, in _create_connection
    return _ConnectionRecord(self)
  File "/usr/local/lib/python3.7/site-packages/sqlalchemy/pool/base.py", line 362, in __init__
    self.__connect(first_connect_check=True)
  File "/usr/local/lib/python3.7/site-packages/sqlalchemy/pool/base.py", line 605, in __connect
    pool.logger.debug("Error on connect(): %s", e)
  File "/usr/local/lib/python3.7/site-packages/sqlalchemy/util/langhelpers.py", line 72, in __exit__
    with_traceback=exc_tb,
  File "/usr/local/lib/python3.7/site-packages/sqlalchemy/util/compat.py", line 211, in raise_
    raise exception
  File "/usr/local/lib/python3.7/site-packages/sqlalchemy/pool/base.py", line 599, in __connect
    connection = pool._invoke_creator(self)
  File "/usr/local/lib/python3.7/site-packages/sqlalchemy/engine/create.py", line 578, in connect
    return dialect.connect(*cargs, **cparams)
  File "/usr/local/lib/python3.7/site-packages/sqlalchemy/engine/default.py", line 583, in connect
    return self.dbapi.connect(*cargs, **cparams)
  File "/usr/local/lib/python3.7/site-packages/psycopg2/__init__.py", line 122, in connect
    conn = _connect(dsn, connection_factory=connection_factory, **kwasync)
psycopg2.OperationalError: could not translate host name "postgres" to address: Temporary failure in name resolution


The above exception was the direct cause of the following exception:

Traceback (most recent call last):
  File "/usr/local/lib/python3.7/site-packages/airflow/jobs/base_job.py", line 201, in heartbeat
    session.merge(self)
  File "/usr/local/lib/python3.7/site-packages/sqlalchemy/orm/session.py", line 2877, in merge
    _resolve_conflict_map=_resolve_conflict_map,
  File "/usr/local/lib/python3.7/site-packages/sqlalchemy/orm/session.py", line 2950, in _merge
    merged = self.get(mapper.class_, key[1], identity_token=key[2])
  File "/usr/local/lib/python3.7/site-packages/sqlalchemy/orm/session.py", line 2702, in get
    identity_token=identity_token,
  File "/usr/local/lib/python3.7/site-packages/sqlalchemy/orm/session.py", line 2800, in _get_impl
    load_options=load_options,
  File "/usr/local/lib/python3.7/site-packages/sqlalchemy/orm/loading.py", line 535, in load_on_pk_identity
    bind_arguments=bind_arguments,
  File "/usr/local/lib/python3.7/site-packages/sqlalchemy/orm/session.py", line 1669, in execute
    conn = self._connection_for_bind(bind, close_with_result=True)
  File "/usr/local/lib/python3.7/site-packages/sqlalchemy/orm/session.py", line 1520, in _connection_for_bind
    engine, execution_options
  File "/usr/local/lib/python3.7/site-packages/sqlalchemy/orm/session.py", line 747, in _connection_for_bind
    conn = bind.connect()
  File "/usr/local/lib/python3.7/site-packages/sqlalchemy/engine/base.py", line 3095, in connect
    return self._connection_cls(self, close_with_result=close_with_result)
  File "/usr/local/lib/python3.7/site-packages/sqlalchemy/engine/base.py", line 91, in __init__
    else engine.raw_connection()
  File "/usr/local/lib/python3.7/site-packages/sqlalchemy/engine/base.py", line 3174, in raw_connection
    return self._wrap_pool_connect(self.pool.connect, _connection)
  File "/usr/local/lib/python3.7/site-packages/sqlalchemy/engine/base.py", line 3145, in _wrap_pool_connect
    e, dialect, self
  File "/usr/local/lib/python3.7/site-packages/sqlalchemy/engine/base.py", line 2004, in _handle_dbapi_exception_noconnection
    sqlalchemy_exception, with_traceback=exc_info[2], from_=e
  File "/usr/local/lib/python3.7/site-packages/sqlalchemy/util/compat.py", line 211, in raise_
    raise exception
  File "/usr/local/lib/python3.7/site-packages/sqlalchemy/engine/base.py", line 3141, in _wrap_pool_connect
    return fn()
  File "/usr/local/lib/python3.7/site-packages/sqlalchemy/pool/base.py", line 301, in connect
    return _ConnectionFairy._checkout(self)
  File "/usr/local/lib/python3.7/site-packages/sqlalchemy/pool/base.py", line 755, in _checkout
    fairy = _ConnectionRecord.checkout(pool)
  File "/usr/local/lib/python3.7/site-packages/sqlalchemy/pool/base.py", line 419, in checkout
    rec = pool._do_get()
  File "/usr/local/lib/python3.7/site-packages/sqlalchemy/pool/impl.py", line 259, in _do_get
    return self._create_connection()
  File "/usr/local/lib/python3.7/site-packages/sqlalchemy/pool/base.py", line 247, in _create_connection
    return _ConnectionRecord(self)
  File "/usr/local/lib/python3.7/site-packages/sqlalchemy/pool/base.py", line 362, in __init__
    self.__connect(first_connect_check=True)
  File "/usr/local/lib/python3.7/site-packages/sqlalchemy/pool/base.py", line 605, in __connect
    pool.logger.debug("Error on connect(): %s", e)
  File "/usr/local/lib/python3.7/site-packages/sqlalchemy/util/langhelpers.py", line 72, in __exit__
    with_traceback=exc_tb,
  File "/usr/local/lib/python3.7/site-packages/sqlalchemy/util/compat.py", line 211, in raise_
    raise exception
  File "/usr/local/lib/python3.7/site-packages/sqlalchemy/pool/base.py", line 599, in __connect
    connection = pool._invoke_creator(self)
  File "/usr/local/lib/python3.7/site-packages/sqlalchemy/engine/create.py", line 578, in connect
    return dialect.connect(*cargs, **cparams)
  File "/usr/local/lib/python3.7/site-packages/sqlalchemy/engine/default.py", line 583, in connect
    return self.dbapi.connect(*cargs, **cparams)
  File "/usr/local/lib/python3.7/site-packages/psycopg2/__init__.py", line 122, in connect
    conn = _connect(dsn, connection_factory=connection_factory, **kwasync)
sqlalchemy.exc.OperationalError: (psycopg2.OperationalError) could not translate host name "postgres" to address: Temporary failure in name resolution

(Background on this error at: http://sqlalche.me/e/14/e3q8)
[2023-03-02 13:42:06,421] {spark_submit.py:495} INFO - 23/03/02 13:42:06 INFO AsyncEventQueue: Process of event SparkListenerExecutorMetricsUpdate(driver,WrappedArray(),Map((-1,-1) -> org.apache.spark.executor.ExecutorMetrics@cff14b1)) by listener AppStatusListener took 1.748338981s.
[2023-03-02 13:42:35,733] {local_task_job.py:221} WARNING - State of this instance has been externally set to scheduled. Terminating instance.
[2023-03-02 13:42:36,181] {process_utils.py:129} INFO - Sending Signals.SIGTERM to group 498. PIDs of all processes in the group: [499, 552, 498]
[2023-03-02 13:42:36,256] {process_utils.py:80} INFO - Sending the signal Signals.SIGTERM to group 498
[2023-03-02 13:42:36,314] {taskinstance.py:1541} ERROR - Received SIGTERM. Terminating subprocesses.
[2023-03-02 13:42:36,331] {spark_submit.py:620} INFO - Sending kill signal to spark-submit
[2023-03-02 13:42:36,713] {process_utils.py:75} INFO - Process psutil.Process(pid=552, status='terminated', started='13:38:32') (552) terminated with exit code None
[2023-03-02 13:42:37,345] {taskinstance.py:1889} ERROR - Task failed with exception
Traceback (most recent call last):
  File "/usr/local/lib/python3.7/site-packages/airflow/providers/apache/spark/operators/spark_submit.py", line 157, in execute
    self._hook.submit(self._application)
  File "/usr/local/lib/python3.7/site-packages/airflow/providers/apache/spark/hooks/spark_submit.py", line 414, in submit
    self._process_spark_submit_log(iter(self._submit_sp.stdout))  # type: ignore
  File "/usr/local/lib/python3.7/site-packages/airflow/providers/apache/spark/hooks/spark_submit.py", line 463, in _process_spark_submit_log
    for line in itr:
  File "/usr/local/lib/python3.7/site-packages/airflow/models/taskinstance.py", line 1543, in signal_handler
    raise AirflowException("Task received SIGTERM signal")
airflow.exceptions.AirflowException: Task received SIGTERM signal
[2023-03-02 13:42:37,507] {taskinstance.py:1400} INFO - Marking task as FAILED. dag_id=avg_product_price, task_id=spark_submit, execution_date=20230302T133816, start_date=20230302T133823, end_date=20230302T134237
[2023-03-02 13:42:37,631] {standard_task_runner.py:97} ERROR - Failed to execute job 7 for task spark_submit (Task received SIGTERM signal; 498)
[2023-03-02 13:42:37,733] {process_utils.py:75} INFO - Process psutil.Process(pid=498, status='terminated', exitcode=1, started='13:38:22') (498) terminated with exit code 1
[2023-03-02 13:43:36,331] {process_utils.py:143} WARNING - process psutil.Process(pid=499, name='java', status='zombie', started='13:38:23') did not respond to SIGTERM. Trying SIGKILL
[2023-03-02 13:43:36,357] {process_utils.py:80} INFO - Sending the signal Signals.SIGKILL to group 498
[2023-03-02 13:44:42,757] {process_utils.py:154} ERROR - Process psutil.Process(pid=499, name='java', status='zombie', started='13:38:23') (499) could not be killed. Giving up.
